INFO: Starting training:
        Epochs:          5
        Batch size:      1
        Learning rate:   1e-05
        Training size:   11
        Validation size: 1
        Checkpoints:     True
        Device:          cuda
        Images scaling:  0.5
        Mixed Precision: False
Epoch 1/5:   9%|â–‰         | 1/11 [00:05<00:50,  5.02s/img, loss (batch)=1.24]
Traceback (most recent call last):
  File "D:\Codes\Pytorch-UNet\venv\lib\site-packages\torch\utils\data\dataloader.py", line 990, in _try_get_data
    data = self._data_queue.get(timeout=timeout)
  File "C:\Users\Lil Tiger\AppData\Local\Programs\Python\Python39\lib\queue.py", line 179, in get
    raise Empty
_queue.Empty
The above exception was the direct cause of the following exception:
Traceback (most recent call last):
  File "C:\Users\Lil Tiger\AppData\Local\Programs\Python\Python39\lib\code.py", line 90, in runcode
    exec(code, self.locals)
  File "<input>", line 1, in <module>
  File "C:\Program Files\JetBrains\PyCharm 2021.2.2\plugins\python\helpers\pydev\_pydev_bundle\pydev_umd.py", line 198, in runfile
    pydev_imports.execfile(filename, global_vars, local_vars)  # execute the script
  File "C:\Program Files\JetBrains\PyCharm 2021.2.2\plugins\python\helpers\pydev\_pydev_imps\_pydev_execfile.py", line 18, in execfile
    exec(compile(contents+"\n", file, 'exec'), glob, loc)
  File "D:/Codes/Pytorch-UNet/train.py", line 182, in <module>
    train_net(net=net,
  File "D:/Codes/Pytorch-UNet/train.py", line 121, in train_net
    val_score = evaluate(net, val_loader, device)
  File "D:\Codes\Pytorch-UNet\evaluate.py", line 14, in evaluate
    for batch in tqdm(dataloader, total=num_val_batches, desc='Validation round', unit='batch', leave=False):
  File "D:\Codes\Pytorch-UNet\venv\lib\site-packages\tqdm\std.py", line 1180, in __iter__
    for obj in iterable:
  File "D:\Codes\Pytorch-UNet\venv\lib\site-packages\torch\utils\data\dataloader.py", line 521, in __next__
    data = self._next_data()
  File "D:\Codes\Pytorch-UNet\venv\lib\site-packages\torch\utils\data\dataloader.py", line 1186, in _next_data
    idx, data = self._get_data()
  File "D:\Codes\Pytorch-UNet\venv\lib\site-packages\torch\utils\data\dataloader.py", line 1142, in _get_data
    success, data = self._try_get_data()
  File "D:\Codes\Pytorch-UNet\venv\lib\site-packages\torch\utils\data\dataloader.py", line 1003, in _try_get_data
    raise RuntimeError('DataLoader worker (pid(s) {}) exited unexpectedly'.format(pids_str)) from e
