2021-10-21 22:07:05,391 INFO    MainThread:17532 [internal.py:wandb_internal():88] W&B internal server running at pid: 17532, started at: 2021-10-21 22:07:05.391580
2021-10-21 22:07:05,392 INFO    WriterThread:17532 [datastore.py:open_for_write():77] open: D:\Codes\Pytorch-UNet\wandb\run-20211021_220704-20cr2t6x\run-20cr2t6x.wandb
2021-10-21 22:07:05,393 DEBUG   HandlerThread:17532 [handler.py:handle_request():130] handle_request: check_version
2021-10-21 22:07:05,394 DEBUG   SenderThread:17532 [sender.py:send():185] send: header
2021-10-21 22:07:05,394 DEBUG   SenderThread:17532 [sender.py:send_request():199] send_request: check_version
2021-10-21 22:07:05,423 DEBUG   SenderThread:17532 [sender.py:send():185] send: run
2021-10-21 22:07:05,425 INFO    SenderThread:17532 [sender.py:_maybe_setup_resume():450] checking resume status for None/U-Net/20cr2t6x
2021-10-21 22:07:08,673 ERROR   SenderThread:17532 [retry.py:__call__():126] Retry attempt failed:
Traceback (most recent call last):
  File "D:\Codes\Pytorch-UNet\venv\lib\site-packages\urllib3\connectionpool.py", line 696, in urlopen
    self._prepare_proxy(conn)
  File "D:\Codes\Pytorch-UNet\venv\lib\site-packages\urllib3\connectionpool.py", line 964, in _prepare_proxy
    conn.connect()
  File "D:\Codes\Pytorch-UNet\venv\lib\site-packages\urllib3\connection.py", line 364, in connect
    conn = self._connect_tls_proxy(hostname, conn)
  File "D:\Codes\Pytorch-UNet\venv\lib\site-packages\urllib3\connection.py", line 501, in _connect_tls_proxy
    socket = ssl_wrap_socket(
  File "D:\Codes\Pytorch-UNet\venv\lib\site-packages\urllib3\util\ssl_.py", line 453, in ssl_wrap_socket
    ssl_sock = _ssl_wrap_socket_impl(sock, context, tls_in_tls)
  File "D:\Codes\Pytorch-UNet\venv\lib\site-packages\urllib3\util\ssl_.py", line 495, in _ssl_wrap_socket_impl
    return ssl_context.wrap_socket(sock)
  File "C:\Users\Lil Tiger\AppData\Local\Programs\Python\Python39\lib\ssl.py", line 500, in wrap_socket
    return self.sslsocket_class._create(
  File "C:\Users\Lil Tiger\AppData\Local\Programs\Python\Python39\lib\ssl.py", line 1040, in _create
    self.do_handshake()
  File "C:\Users\Lil Tiger\AppData\Local\Programs\Python\Python39\lib\ssl.py", line 1309, in do_handshake
    self._sslobj.do_handshake()
ssl.SSLEOFError: EOF occurred in violation of protocol (_ssl.c:1129)

During handling of the above exception, another exception occurred:

Traceback (most recent call last):
  File "D:\Codes\Pytorch-UNet\venv\lib\site-packages\requests\adapters.py", line 439, in send
    resp = conn.urlopen(
  File "D:\Codes\Pytorch-UNet\venv\lib\site-packages\urllib3\connectionpool.py", line 755, in urlopen
    retries = retries.increment(
  File "D:\Codes\Pytorch-UNet\venv\lib\site-packages\urllib3\util\retry.py", line 574, in increment
    raise MaxRetryError(_pool, url, error or ResponseError(cause))
urllib3.exceptions.MaxRetryError: HTTPSConnectionPool(host='api.wandb.ai', port=443): Max retries exceeded with url: /graphql (Caused by SSLError(SSLEOFError(8, 'EOF occurred in violation of protocol (_ssl.c:1129)')))

During handling of the above exception, another exception occurred:

Traceback (most recent call last):
  File "D:\Codes\Pytorch-UNet\venv\lib\site-packages\wandb\sdk\lib\retry.py", line 102, in __call__
    result = self._call_fn(*args, **kwargs)
  File "D:\Codes\Pytorch-UNet\venv\lib\site-packages\wandb\sdk\internal\internal_api.py", line 141, in execute
    return self.client.execute(*args, **kwargs)
  File "D:\Codes\Pytorch-UNet\venv\lib\site-packages\wandb\vendor\gql-0.2.0\gql\client.py", line 52, in execute
    result = self._get_result(document, *args, **kwargs)
  File "D:\Codes\Pytorch-UNet\venv\lib\site-packages\wandb\vendor\gql-0.2.0\gql\client.py", line 60, in _get_result
    return self.transport.execute(document, *args, **kwargs)
  File "D:\Codes\Pytorch-UNet\venv\lib\site-packages\wandb\vendor\gql-0.2.0\gql\transport\requests.py", line 38, in execute
    request = requests.post(self.url, **post_args)
  File "D:\Codes\Pytorch-UNet\venv\lib\site-packages\requests\api.py", line 117, in post
    return request('post', url, data=data, json=json, **kwargs)
  File "D:\Codes\Pytorch-UNet\venv\lib\site-packages\requests\api.py", line 61, in request
    return session.request(method=method, url=url, **kwargs)
  File "D:\Codes\Pytorch-UNet\venv\lib\site-packages\requests\sessions.py", line 542, in request
    resp = self.send(prep, **send_kwargs)
  File "D:\Codes\Pytorch-UNet\venv\lib\site-packages\requests\sessions.py", line 655, in send
    r = adapter.send(request, **kwargs)
  File "D:\Codes\Pytorch-UNet\venv\lib\site-packages\requests\adapters.py", line 514, in send
    raise SSLError(e, request=request)
requests.exceptions.SSLError: HTTPSConnectionPool(host='api.wandb.ai', port=443): Max retries exceeded with url: /graphql (Caused by SSLError(SSLEOFError(8, 'EOF occurred in violation of protocol (_ssl.c:1129)')))
2021-10-21 22:07:30,622 WARNING MainThread:17532 [internal.py:is_dead():367] Internal process exiting, parent pid 18652 disappeared
2021-10-21 22:07:30,622 ERROR   MainThread:17532 [internal.py:wandb_internal():143] Internal process shutdown.
2021-10-21 22:07:30,664 INFO    WriterThread:17532 [datastore.py:close():281] close: D:\Codes\Pytorch-UNet\wandb\run-20211021_220704-20cr2t6x\run-20cr2t6x.wandb
2021-10-21 22:07:30,664 INFO    HandlerThread:17532 [handler.py:finish():731] shutting down handler
