2021-10-21 22:13:41,396 INFO    MainThread:14244 [internal.py:wandb_internal():88] W&B internal server running at pid: 14244, started at: 2021-10-21 22:13:41.396318
2021-10-21 22:13:41,398 INFO    WriterThread:14244 [datastore.py:open_for_write():77] open: D:\Codes\Pytorch-UNet\wandb\run-20211021_221340-2trbezrn\run-2trbezrn.wandb
2021-10-21 22:13:41,398 DEBUG   HandlerThread:14244 [handler.py:handle_request():130] handle_request: check_version
2021-10-21 22:13:41,399 DEBUG   SenderThread:14244 [sender.py:send():185] send: header
2021-10-21 22:13:41,399 DEBUG   SenderThread:14244 [sender.py:send_request():199] send_request: check_version
2021-10-21 22:13:43,439 DEBUG   SenderThread:14244 [sender.py:send():185] send: run
2021-10-21 22:13:43,441 INFO    SenderThread:14244 [sender.py:_maybe_setup_resume():450] checking resume status for None/U-Net/2trbezrn
2021-10-21 22:13:52,951 ERROR   SenderThread:14244 [retry.py:__call__():126] Retry attempt failed:
Traceback (most recent call last):
  File "D:\Codes\Pytorch-UNet\venv\lib\site-packages\urllib3\connection.py", line 174, in _new_conn
    conn = connection.create_connection(
  File "D:\Codes\Pytorch-UNet\venv\lib\site-packages\urllib3\util\connection.py", line 96, in create_connection
    raise err
  File "D:\Codes\Pytorch-UNet\venv\lib\site-packages\urllib3\util\connection.py", line 86, in create_connection
    sock.connect(sa)
ConnectionRefusedError: [WinError 10061] 由于目标计算机积极拒绝，无法连接。

During handling of the above exception, another exception occurred:

Traceback (most recent call last):
  File "D:\Codes\Pytorch-UNet\venv\lib\site-packages\urllib3\connectionpool.py", line 696, in urlopen
    self._prepare_proxy(conn)
  File "D:\Codes\Pytorch-UNet\venv\lib\site-packages\urllib3\connectionpool.py", line 964, in _prepare_proxy
    conn.connect()
  File "D:\Codes\Pytorch-UNet\venv\lib\site-packages\urllib3\connection.py", line 358, in connect
    conn = self._new_conn()
  File "D:\Codes\Pytorch-UNet\venv\lib\site-packages\urllib3\connection.py", line 186, in _new_conn
    raise NewConnectionError(
urllib3.exceptions.NewConnectionError: <urllib3.connection.HTTPSConnection object at 0x00000290E0CACE20>: Failed to establish a new connection: [WinError 10061] 由于目标计算机积极拒绝，无法连接。

During handling of the above exception, another exception occurred:

Traceback (most recent call last):
  File "D:\Codes\Pytorch-UNet\venv\lib\site-packages\requests\adapters.py", line 439, in send
    resp = conn.urlopen(
  File "D:\Codes\Pytorch-UNet\venv\lib\site-packages\urllib3\connectionpool.py", line 755, in urlopen
    retries = retries.increment(
  File "D:\Codes\Pytorch-UNet\venv\lib\site-packages\urllib3\util\retry.py", line 574, in increment
    raise MaxRetryError(_pool, url, error or ResponseError(cause))
urllib3.exceptions.MaxRetryError: HTTPSConnectionPool(host='api.wandb.ai', port=443): Max retries exceeded with url: /graphql (Caused by ProxyError('Cannot connect to proxy.', NewConnectionError('<urllib3.connection.HTTPSConnection object at 0x00000290E0CACE20>: Failed to establish a new connection: [WinError 10061] 由于目标计算机积极拒绝，无法连接。')))

During handling of the above exception, another exception occurred:

Traceback (most recent call last):
  File "D:\Codes\Pytorch-UNet\venv\lib\site-packages\wandb\sdk\lib\retry.py", line 102, in __call__
    result = self._call_fn(*args, **kwargs)
  File "D:\Codes\Pytorch-UNet\venv\lib\site-packages\wandb\sdk\internal\internal_api.py", line 141, in execute
    return self.client.execute(*args, **kwargs)
  File "D:\Codes\Pytorch-UNet\venv\lib\site-packages\wandb\vendor\gql-0.2.0\gql\client.py", line 52, in execute
    result = self._get_result(document, *args, **kwargs)
  File "D:\Codes\Pytorch-UNet\venv\lib\site-packages\wandb\vendor\gql-0.2.0\gql\client.py", line 60, in _get_result
    return self.transport.execute(document, *args, **kwargs)
  File "D:\Codes\Pytorch-UNet\venv\lib\site-packages\wandb\vendor\gql-0.2.0\gql\transport\requests.py", line 38, in execute
    request = requests.post(self.url, **post_args)
  File "D:\Codes\Pytorch-UNet\venv\lib\site-packages\requests\api.py", line 117, in post
    return request('post', url, data=data, json=json, **kwargs)
  File "D:\Codes\Pytorch-UNet\venv\lib\site-packages\requests\api.py", line 61, in request
    return session.request(method=method, url=url, **kwargs)
  File "D:\Codes\Pytorch-UNet\venv\lib\site-packages\requests\sessions.py", line 542, in request
    resp = self.send(prep, **send_kwargs)
  File "D:\Codes\Pytorch-UNet\venv\lib\site-packages\requests\sessions.py", line 655, in send
    r = adapter.send(request, **kwargs)
  File "D:\Codes\Pytorch-UNet\venv\lib\site-packages\requests\adapters.py", line 510, in send
    raise ProxyError(e, request=request)
requests.exceptions.ProxyError: HTTPSConnectionPool(host='api.wandb.ai', port=443): Max retries exceeded with url: /graphql (Caused by ProxyError('Cannot connect to proxy.', NewConnectionError('<urllib3.connection.HTTPSConnection object at 0x00000290E0CACE20>: Failed to establish a new connection: [WinError 10061] 由于目标计算机积极拒绝，无法连接。')))
2021-10-21 22:14:13,453 DEBUG   HandlerThread:14244 [handler.py:handle_request():130] handle_request: shutdown
2021-10-21 22:14:13,453 INFO    HandlerThread:14244 [handler.py:finish():731] shutting down handler
2021-10-21 22:14:13,643 INFO    WriterThread:14244 [datastore.py:close():281] close: D:\Codes\Pytorch-UNet\wandb\run-20211021_221340-2trbezrn\run-2trbezrn.wandb
2021-10-21 22:18:38,812 INFO    SenderThread:14244 [dir_watcher.py:__init__():169] watching files in: D:\Codes\Pytorch-UNet\wandb\run-20211021_221340-2trbezrn\files
2021-10-21 22:18:38,812 INFO    SenderThread:14244 [sender.py:_start_run_threads():768] run started: 2trbezrn with start time 1634825621
2021-10-21 22:18:38,812 INFO    SenderThread:14244 [sender.py:finish():1029] shutting down sender
2021-10-21 22:18:38,812 INFO    SenderThread:14244 [dir_watcher.py:finish():283] shutting down directory watcher
2021-10-21 22:18:39,815 INFO    SenderThread:14244 [dir_watcher.py:finish():313] scan: D:\Codes\Pytorch-UNet\wandb\run-20211021_221340-2trbezrn\files
2021-10-21 22:18:39,815 INFO    SenderThread:14244 [dir_watcher.py:finish():327] scan save: D:\Codes\Pytorch-UNet\wandb\run-20211021_221340-2trbezrn\files\config.yaml config.yaml
2021-10-21 22:18:39,816 INFO    SenderThread:14244 [file_pusher.py:finish():177] shutting down file pusher
2021-10-21 22:18:39,816 INFO    SenderThread:14244 [file_pusher.py:join():182] waiting for file pusher
2021-10-21 22:18:41,493 INFO    Thread-14 :14244 [upload_job.py:push():137] Uploaded file D:\Codes\Pytorch-UNet\wandb\run-20211021_221340-2trbezrn\files\config.yaml
2021-10-21 22:18:42,265 INFO    MainThread:14244 [internal.py:handle_exit():78] Internal process exited
